<mujoco model="strirus_gamma">
    <compiler convexhull="false" angle="radian" meshdir="../../../../strirus_cad_design/stl/collision/" />

    <default>
        <joint limited="true" damping="1" armature="0"/>
        <geom condim="3"/>
        <position ctrlrange="-100 100" ctrllimited="true" forcerange="-3 3" forcelimited="true"/>
    </default>


    <size njmax="500" nconmax="100" />
    <include file="terrain.xml"/>
    <asset>
        <mesh name="body_1_30_part" file="body_1_30_part.stl" />
        <mesh name="body_2_30_part" file="body_2_30_part.stl" />
        <mesh name="bridge_1_part" file="bridge_1_part.stl" />
        <mesh name="bridge_2_part" file="bridge_2_part.stl" />
        <mesh name="leg_70" file="leg_70.stl" />
    </asset>
    <worldbody>
        <body name="body_1_part" pos="0 0 0.07">
            <freejoint/>
            <inertial pos="0.0930046 -3.767e-06 -0.00239317" quat="0.501994 0.501944 -0.498044 0.498002" mass="2.38893" diaginertia="0.0438695 0.0286149 0.0162443" />
            <geom type="mesh" mesh="body_1_30_part" />
            <body name="bridge_1_part" pos="0.247 0 0">
                <inertial pos="0.00668872 0 7.7504e-05" quat="0.707088 0.707088 -0.00517401 0.00517401" mass="0.0934526" diaginertia="0.000234668 0.000231387 2.9584e-05" />
                <joint name="segment_side_revolute" pos="0 0 0" axis="0 0 -1" limited="true" range="-0.261799 0.261799" stiffness="20"/>
                <geom type="mesh" mesh="bridge_1_part" />
                <body name="bridge_2_part" pos="0.03 0 0">
                    <inertial pos="0.0233113 0 7.7504e-05" quat="0.707088 0.707088 -0.00517243 0.00517243" mass="0.0934526" diaginertia="0.000215113 0.000211831 2.9584e-05" />
                    <joint name="segment_up_revolute" pos="0 0 0" axis="0 -1 0" limited="true" range="-1.309 1.309" stiffness="20"/>
                    <geom type="mesh" mesh="bridge_2_part" />
                    <body name="body_2_part" pos="0.03 0 0">
                        <inertial pos="0.154054 5.875e-06 -0.00271984" quat="0.49812 0.498053 -0.501941 0.50187" mass="2.35583" diaginertia="0.0438457 0.0285897 0.0162089" />
                        <geom type="mesh" mesh="body_2_30_part" />
                        <body name="leg_left_5" pos="0.06325 0.17893 0" quat="0.482963 -0.224144 -0.836516 -0.12941">
                            <inertial pos="-0.0133487 0 -0.0275841" quat="0.703293 -0.073343 -0.073343 0.703293" mass="0.0127063" diaginertia="9.763e-06 8.16912e-06 1.72988e-06" />
                            <joint name="leg_left_5_revolute_joint" pos="0 0 0" axis="0 1 0" limited="true" range="-100000 100000" />
                            <geom type="mesh" mesh="leg_70" />
                        </body>
                        <body name="leg_left_4" pos="0.16925 0.17893 0" quat="-0.482963 -0.224144 -0.836516 0.12941">
                            <inertial pos="-0.0133487 0 -0.0275841" quat="0.703293 -0.073343 -0.073343 0.703293" mass="0.0127063" diaginertia="9.763e-06 8.16912e-06 1.72988e-06" />
                            <joint name="leg_left_4_revolute_joint" pos="0 0 0" axis="0 1 0" limited="true" range="-100000 100000" />
                            <geom type="mesh" mesh="leg_70" />
                        </body>
                        <body name="leg_left_3" pos="0.27525 0.17893 0" quat="-0.965926 0 0 0.258819">
                            <inertial pos="-0.0133487 0 -0.0275841" quat="0.703293 -0.073343 -0.073343 0.703293" mass="0.0127063" diaginertia="9.763e-06 8.16912e-06 1.72988e-06" />
                            <joint name="leg_left_3_revolute_joint" pos="0 0 0" axis="0 1 0" limited="true" range="-100000 100000" />
                            <geom type="mesh" mesh="leg_70" />
                        </body>
                        <body name="leg_right_5" pos="0.06325 -0.17893 0" quat="0.482963 0.224144 -0.836516 0.12941">
                            <inertial pos="-0.0133487 0 -0.0275841" quat="0.703293 -0.073343 -0.073343 0.703293" mass="0.0127063" diaginertia="9.763e-06 8.16912e-06 1.72988e-06" />
                            <joint name="leg_right_5_revolute_joint" pos="0 0 0" axis="0 1 0" limited="true" range="-100000 100000" />
                            <geom type="mesh" mesh="leg_70" />
                        </body>
                        <body name="leg_right_4" pos="0.16925 -0.17893 0" quat="-0.482963 0.224144 -0.836516 -0.12941">
                            <inertial pos="-0.0133487 0 -0.0275841" quat="0.703293 -0.073343 -0.073343 0.703293" mass="0.0127063" diaginertia="9.763e-06 8.16912e-06 1.72988e-06" />
                            <joint name="leg_right_4_revolute_joint" pos="0 0 0" axis="0 1 0" limited="true" range="-100000 100000" />
                            <geom type="mesh" mesh="leg_70" />
                        </body>
                        <body name="leg_right_3" pos="0.27525 -0.17893 0" quat="-0.965926 0 0 -0.258819">
                            <inertial pos="-0.0133487 0 -0.0275841" quat="0.703293 -0.073343 -0.073343 0.703293" mass="0.0127063" diaginertia="9.763e-06 8.16912e-06 1.72988e-06" />
                            <joint name="leg_right_3_revolute_joint" pos="0 0 0" axis="0 1 0" limited="true" range="-100000 100000" />
                            <geom type="mesh" mesh="leg_70" />
                        </body>
                    </body>
                </body>
            </body>
            <body name="leg_left_2" pos="0.18375 0.17893 0" quat="-0.482963 -0.224144 0.836516 -0.12941">
                <inertial pos="-0.0133487 0 -0.0275841" quat="0.703293 -0.073343 -0.073343 0.703293" mass="0.0127063" diaginertia="9.763e-06 8.16912e-06 1.72988e-06" />
                <joint name="leg_left_2_revolute_joint" pos="0 0 0" axis="0 1 0" limited="true" range="-100000 100000" />
                <geom type="mesh" mesh="leg_70" />
            </body>
            <body name="leg_left_1" pos="0.07775 0.17893 0" quat="0.482963 -0.224144 0.836516 0.12941">
                <inertial pos="-0.0133487 0 -0.0275841" quat="0.703293 -0.073343 -0.073343 0.703293" mass="0.0127063" diaginertia="9.763e-06 8.16912e-06 1.72988e-06" />
                <joint name="leg_left_1_revolute_joint" pos="0 0 0" axis="0 1 0" limited="true" range="-100000 100000" />
                <geom type="mesh" mesh="leg_70" />
            </body>
            <body name="leg_left_0" pos="-0.02825 0.17893 0" quat="0.965926 0 0 0.258819">
                <inertial pos="-0.0133487 0 -0.0275841" quat="0.703293 -0.073343 -0.073343 0.703293" mass="0.0127063" diaginertia="9.763e-06 8.16912e-06 1.72988e-06" />
                <joint name="leg_left_0_revolute_joint" pos="0 0 0" axis="0 1 0" limited="true" range="-100000 100000" />
                <geom type="mesh" mesh="leg_70" />
            </body>
            <body name="leg_right_2" pos="0.18375 -0.17893 0" quat="-0.482963 0.224144 0.836516 0.12941">
                <inertial pos="-0.0133487 0 -0.0275841" quat="0.703293 -0.073343 -0.073343 0.703293" mass="0.0127063" diaginertia="9.763e-06 8.16912e-06 1.72988e-06" />
                <joint name="leg_right_2_revolute_joint" pos="0 0 0" axis="0 1 0" limited="true" range="-100000 100000" />
                <geom type="mesh" mesh="leg_70" />
            </body>
            <body name="leg_right_1" pos="0.07775 -0.17893 0" quat="0.482963 0.224144 0.836516 -0.12941">
                <inertial pos="-0.0133487 0 -0.0275841" quat="0.703293 -0.073343 -0.073343 0.703293" mass="0.0127063" diaginertia="9.763e-06 8.16912e-06 1.72988e-06" />
                <joint name="leg_right_1_revolute_joint" pos="0 0 0" axis="0 1 0" limited="true" range="-100000 100000" />
                <geom type="mesh" mesh="leg_70" />
            </body>
            <body name="leg_right_0" pos="-0.02825 -0.17893 0" quat="0.965926 0 0 -0.258819">
                <inertial pos="-0.0133487 0 -0.0275841" quat="0.703293 -0.073343 -0.073343 0.703293" mass="0.0127063" diaginertia="9.763e-06 8.16912e-06 1.72988e-06" />
                <joint name="leg_right_0_revolute_joint" pos="0 0 0" axis="0 1 0" limited="true" range="-100000 100000" />
                <geom type="mesh" mesh="leg_70" />
            </body>
        </body>
    </worldbody>

    <actuator>
        <position name="leg_left_0_revolute_joint" joint="leg_left_0_revolute_joint" />
	<position name="leg_left_1_revolute_joint" joint="leg_left_1_revolute_joint" />
	<position name="leg_left_2_revolute_joint" joint="leg_left_2_revolute_joint" />
	<position name="leg_left_3_revolute_joint" joint="leg_left_3_revolute_joint" />
	<position name="leg_left_4_revolute_joint" joint="leg_left_4_revolute_joint" />
	<position name="leg_left_5_revolute_joint" joint="leg_left_5_revolute_joint" />
        <position name="leg_right_0_revolute_joint" joint="leg_right_0_revolute_joint" />
	<position name="leg_right_1_revolute_joint" joint="leg_right_1_revolute_joint" />
	<position name="leg_right_2_revolute_joint" joint="leg_right_2_revolute_joint" />
	<position name="leg_right_3_revolute_joint" joint="leg_right_3_revolute_joint" />
	<position name="leg_right_4_revolute_joint" joint="leg_right_4_revolute_joint" />
	<position name="leg_right_5_revolute_joint" joint="leg_right_5_revolute_joint" />
    </actuator>

    <sensor>
	<actuatorpos name="leg_left_0_angle_act" actuator="leg_left_0_revolute_joint" />
	<actuatorpos name="leg_left_1_angle_act" actuator="leg_left_1_revolute_joint" />
	<actuatorpos name="leg_left_2_angle_act" actuator="leg_left_2_revolute_joint" />
	<actuatorpos name="leg_left_3_angle_act" actuator="leg_left_3_revolute_joint" />
	<actuatorpos name="leg_left_4_angle_act" actuator="leg_left_4_revolute_joint" />
	<actuatorpos name="leg_left_5_angle_act" actuator="leg_left_5_revolute_joint" />
	<actuatorpos name="leg_right_0_angle_act" actuator="leg_right_0_revolute_joint" />
	<actuatorpos name="leg_right_1_angle_act" actuator="leg_right_1_revolute_joint" />
	<actuatorpos name="leg_right_2_angle_act" actuator="leg_right_2_revolute_joint" />
	<actuatorpos name="leg_right_3_angle_act" actuator="leg_right_3_revolute_joint" />
	<actuatorpos name="leg_right_4_angle_act" actuator="leg_right_4_revolute_joint" />
	<actuatorpos name="leg_right_5_angle_act" actuator="leg_right_5_revolute_joint" />
	<framequat name="frameQuatBody1" objtype="body" objname="body_1_part" />
	<framequat name="frameQuatBody2" objtype="body" objname="body_2_part" />
    </sensor>

</mujoco>
